<?xml version="1.0"?>
<sdf version="1.9">
  <model name="plane04">
    <pose>0 0 0.246 0 0 0</pose>

    <link name="base_link">
      <pose>0 0 0 0 0 0</pose>
      <inertial>
        <mass>1.5</mass>
        <inertia>
          <ixx>0.197563</ixx><ixy>0</ixy><ixz>0</ixz>
          <iyy>0.1458929</iyy><iyz>0</iyz>
          <izz>0.1477</izz>
        </inertia>
      </inertial>
      <collision name="base_link_collision">
        <pose>0 0 -0.07 0 0 0</pose>
        <geometry><box><size>0.47 0.47 0.11</size></box></geometry>
      </collision>
      <visual name="base_link_visual">
        <pose>0.07 0 -0.08 0 0 0</pose>
        <geometry>
          <mesh><scale>0.1 0.1 0.1</scale><uri>model://plane/meshes/body.dae</uri></mesh>
        </geometry>
        <material><ambient>0.6 0.6 0.6 1</ambient><diffuse>0.6 0.6 0.6 1</diffuse></material>
      </visual>
    </link>

    <link name="imu_link">
      <pose>0 0 0 0 0 0</pose>
      <inertial>
        <mass>0.015</mass>
        <inertia><ixx>1e-05</ixx><ixy>0</ixy><ixz>0</ixz><iyy>1e-05</iyy><iyz>0</iyz><izz>1e-05</izz></inertia>
      </inertial>
      <sensor name="imu_sensor" type="imu">
        <always_on>1</always_on>
        <update_rate>100</update_rate>
        <imu>
          <angular_velocity>
            <x><noise type="gaussian"><mean>0</mean><stddev>0.0003394</stddev></noise></x>
            <y><noise type="gaussian"><mean>0</mean><stddev>0.0003394</stddev></noise></y>
            <z><noise type="gaussian"><mean>0</mean><stddev>0.0003394</stddev></noise></z>
          </angular_velocity>
          <linear_acceleration>
            <x><noise type="gaussian"><mean>0</mean><stddev>0.004</stddev></noise></x>
            <y><noise type="gaussian"><mean>0</mean><stddev>0.004</stddev></noise></y>
            <z><noise type="gaussian"><mean>0</mean><stddev>0.004</stddev></noise></z>
          </linear_acceleration>
        </imu>
        <topic>/model/plane04/imu</topic>
      </sensor>
      <sensor name="navsat_sensor" type="navsat">
        <always_on>1</always_on>
        <update_rate>10</update_rate>
        <topic>/model/plane04/navsat</topic>
      </sensor>
    </link>

    <joint name="imu_joint" type="fixed">
      <child>imu_link</child>
      <parent>base_link</parent>
    </joint>

    <link name="rotor_puller">
      <pose>0.3 0 0.0 0 1.57 0</pose>
      <inertial>
        <mass>0.005</mass>
        <inertia><ixx>9.75e-07</ixx><ixy>0</ixy><ixz>0</ixz><iyy>0.000166704</iyy><iyz>0</iyz><izz>0.000167604</izz></inertia>
      </inertial>
      <collision name="rotor_puller_collision">
        <geometry><cylinder><length>0.005</length><radius>0.1</radius></cylinder></geometry>
      </collision>
      <visual name="rotor_puller_visual">
        <pose>0 0 -0.09 0 0 0</pose>
        <geometry>
          <mesh><scale>1 1 1</scale><uri>model://plane/meshes/iris_prop_ccw.dae</uri></mesh>
        </geometry>
        <material><ambient>0.2 0.2 0.2 1</ambient><diffuse>0.2 0.2 0.2 1</diffuse></material>
      </visual>
    </link>

    <joint name="rotor_puller_joint" type="revolute">
      <child>rotor_puller</child><parent>base_link</parent>
      <axis>
        <xyz>0 0 1</xyz>
        <limit><lower>-1e+16</lower><upper>1e+16</upper></limit>
        <dynamics><damping>0.004</damping><friction>0.0</friction><spring_reference>0</spring_reference><spring_stiffness>0</spring_stiffness></dynamics>
      </axis>
    </joint>

    <link name="left_elevon">
      <inertial><mass>0.00000001</mass><pose>0 0.3 0 0 0 0</pose>
        <inertia><ixx>0.000001</ixx><ixy>0</ixy><ixz>0</ixz><iyy>0.000001</iyy><iyz>0</iyz><izz>0.000001</izz></inertia>
      </inertial>
      <visual name="left_elevon_visual">
        <pose>0.07 0.0 -0.08 0 0 0</pose>
        <geometry><mesh><scale>0.1 0.1 0.1</scale><uri>model://plane/meshes/left_aileron.dae</uri></mesh></geometry>
        <material><ambient>0.6 0.6 0.6 1</ambient><diffuse>0.6 0.6 0.6 1</diffuse></material>
      </visual>
    </link>
    <link name="right_elevon">
      <inertial><mass>0.00000001</mass><pose>0 -0.3 0 0 0 0</pose>
        <inertia><ixx>0.000001</ixx><ixy>0</ixy><ixz>0</ixz><iyy>0.000001</iyy><iyz>0</iyz><izz>0.000001</izz></inertia>
      </inertial>
      <visual name="right_elevon_visual">
        <pose>0.07 0.0 -0.08 0 0 0</pose>
        <geometry><mesh><scale>0.1 0.1 0.1</scale><uri>model://plane/meshes/right_aileron.dae</uri></mesh></geometry>
        <material><ambient>0.6 0.6 0.6 1</ambient><diffuse>0.6 0.6 0.6 1</diffuse></material>
      </visual>
    </link>
    <link name="elevator">
      <inertial><mass>0.00000001</mass><pose>-0.5 0 0 0 0 0</pose>
        <inertia><ixx>0.000001</ixx><ixy>0</ixy><ixz>0</ixz><iyy>0.000001</iyy><iyz>0</iyz><izz>0.000001</izz></inertia>
      </inertial>
      <visual name="elevator_visual">
        <pose>0.07 0.0 -0.08 0 0 0</pose>
        <geometry><mesh><scale>0.1 0.1 0.1</scale><uri>model://plane/meshes/elevators.dae</uri></mesh></geometry>
        <material><ambient>0.6 0.6 0.6 1</ambient><diffuse>0.6 0.6 0.6 1</diffuse></material>
      </visual>
    </link>
    <link name="rudder">
      <inertial><mass>0.00000001</mass><pose>-0.5 0 0.05 0 0 0</pose>
        <inertia><ixx>0.000001</ixx><ixy>0</ixy><ixz>0</ixz><iyy>0.000001</iyy><iyz>0</iyz><izz>0.000001</izz></inertia>
      </inertial>
      <visual name="rudder_visual">
        <pose>0.07 0.0 -0.08 0 0 0</pose>
        <geometry><mesh><scale>0.1 0.1 0.1</scale><uri>model://plane/meshes/rudder.dae</uri></mesh></geometry>
        <material><ambient>0.6 0.6 0.6 1</ambient><diffuse>0.6 0.6 0.6 1</diffuse></material>
      </visual>
    </link>

    <joint name="left_elevon_joint" type="revolute">
      <parent>base_link</parent><child>left_elevon</child>
      <pose>-0.07 0.4 0.08 0 0 0</pose>
      <axis><xyz>0 1 0</xyz><limit><lower>-0.53</lower><upper>0.53</upper></limit><dynamics><damping>1.0</damping></dynamics></axis>
    </joint>
    <joint name="right_elevon_joint" type="revolute">
      <parent>base_link</parent><child>right_elevon</child>
      <pose>-0.07 -0.4 0.08 0 0 0</pose>
      <axis><xyz>0 1 0</xyz><limit><lower>-0.53</lower><upper>0.53</upper></limit><dynamics><damping>1.0</damping></dynamics></axis>
    </joint>
    <joint name="elevator_joint" type="revolute">
      <parent>base_link</parent><child>elevator</child>
      <pose>-0.5 0 0 0 0 0</pose>
      <axis><xyz>0 1 0</xyz><limit><lower>-0.53</lower><upper>0.53</upper></limit><dynamics><damping>1.0</damping></dynamics></axis>
    </joint>
    <joint name="rudder_joint" type="revolute">
      <parent>base_link</parent><child>rudder</child>
      <pose>-0.5 0 0.05 0 0 0</pose>
      <axis><xyz>0 0 1</xyz><limit><lower>-0.53</lower><upper>0.53</upper></limit><dynamics><damping>1.0</damping></dynamics></axis>
    </joint>

    <!-- Aerodinâmica -->
    <plugin filename="gz-sim-lift-drag-system" name="gz::sim::systems::LiftDrag">
      <a0>0.05984281113</a0><cla>4.752798721</cla><cda>0.6417112299</cda>
      <alpha_stall>0.3391428111</alpha_stall><cla_stall>-3.85</cla_stall><cda_stall>-0.9233984055</cda_stall>
      <cp>-0.05 0.45 0.05</cp><area>0.6</area><air_density>1.2041</air_density>
      <forward>1 0 0</forward><upward>0 0 1</upward><link_name>base_link</link_name>
      <control_joint_name>left_elevon_joint</control_joint_name><control_joint_rad_to_cl>-0.3</control_joint_rad_to_cl>
    </plugin>
    <plugin filename="gz-sim-lift-drag-system" name="gz::sim::systems::LiftDrag">
      <a0>0.05984281113</a0><cla>4.752798721</cla><cda>0.6417112299</cda>
      <alpha_stall>0.3391428111</alpha_stall><cla_stall>-3.85</cla_stall><cda_stall>-0.9233984055</cda_stall>
      <cp>-0.05 -0.45 0.05</cp><area>0.6</area><air_density>1.2041</air_density>
      <forward>1 0 0</forward><upward>0 0 1</upward><link_name>base_link</link_name>
      <control_joint_name>right_elevon_joint</control_joint_name><control_joint_rad_to_cl>-0.3</control_joint_rad_to_cl>
    </plugin>
    <plugin filename="gz-sim-lift-drag-system" name="gz::sim::systems::LiftDrag">
      <a0>-0.2</a0><cla>4.752798721</cla><cda>0.6417112299</cda>
      <alpha_stall>0.3391428111</alpha_stall><cla_stall>-3.85</cla_stall><cda_stall>-0.9233984055</cda_stall>
      <cp>-0.5 0 0</cp><area>0.01</area><air_density>1.2041</air_density>
      <forward>1 0 0</forward><upward>0 0 1</upward><link_name>base_link</link_name>
      <control_joint_name>elevator_joint</control_joint_name><control_joint_rad_to_cl>-4.0</control_joint_rad_to_cl>
    </plugin>
    <plugin filename="gz-sim-lift-drag-system" name="gz::sim::systems::LiftDrag">
      <a0>0.0</a0><cla>4.752798721</cla><cda>0.6417112299</cda>
      <alpha_stall>0.3391428111</alpha_stall><cla_stall>-3.85</cla_stall><cda_stall>-0.9233984055</cda_stall>
      <cp>-0.5 0 0.05</cp><area>0.02</area><air_density>1.2041</air_density>
      <forward>1 0 0</forward><upward>0 1 0</upward><link_name>base_link</link_name>
      <control_joint_name>rudder_joint</control_joint_name><control_joint_rad_to_cl>0.8</control_joint_rad_to_cl>
    </plugin>

    <!-- Motor -->
    <plugin filename="gz-sim-joint-controller-system" name="gz::sim::systems::JointController">
      <joint_name>rotor_puller_joint</joint_name>
      <use_force_commands>false</use_force_commands>
    </plugin>

    <!-- Superfícies de controle -->
    <plugin filename="gz-sim-joint-position-controller-system" name="gz::sim::systems::JointPositionController">
      <joint_name>left_elevon_joint</joint_name>
      <topic>/model/plane04/joint/left_elevon_joint/cmd_pos</topic>
    </plugin>
    <plugin filename="gz-sim-joint-position-controller-system" name="gz::sim::systems::JointPositionController">
      <joint_name>right_elevon_joint</joint_name>
      <topic>/model/plane04/joint/right_elevon_joint/cmd_pos</topic>
    </plugin>
    <plugin filename="gz-sim-joint-position-controller-system" name="gz::sim::systems::JointPositionController">
      <joint_name>elevator_joint</joint_name>
      <topic>/model/plane04/joint/elevator_joint/cmd_pos</topic>
    </plugin>
    <plugin filename="gz-sim-joint-position-controller-system" name="gz::sim::systems::JointPositionController">
      <joint_name>rudder_joint</joint_name>
      <topic>/model/plane04/joint/rudder_joint/cmd_pos</topic>
    </plugin>

    <!-- Odometria -->
    <plugin filename="gz-sim-odometry-publisher-system" name="gz::sim::systems::OdometryPublisher">
      <odom_frame>cosmus_airfield/plane04/odom</odom_frame>
      <robot_base_frame>plane04/base_link</robot_base_frame>
      <odom_topic>/model/plane04/odometry</odom_topic>
      <tf_topic>/model/plane04/tf</tf_topic>
      <dimensions>3</dimensions>
    </plugin>

    <plugin filename="gz-sim-imu-system" name="gz::sim::systems::Imu"/>
    <plugin filename="gz-sim-navsat-system" name="gz::sim::systems::NavSat"/>

    <static>0</static>
  </model>
</sdf>